No exception occured
I am inside finally block
Test Completed
